/usr/local/lib/python3.8/site-packages/torch/nn/functional.py:3060: UserWarning: Default upsampling behavior when mode=bilinear is changed to align_corners=False since 0.4.0. Please specify align_corners=True if the old behavior is desired. See the documentation of nn.Upsample for details.
  warnings.warn("Default upsampling behavior when mode={} is changed "








































Validating: 100% 784/784 [08:01<00:00,  1.63it/s][0.72671551 0.45716567 0.7799057  0.72621868 0.88320499 0.40139122
 0.67602838 0.52044672]
/usr/local/lib/python3.8/site-packages/pytorch_lightning/core/datamodule.py:423: LightningDeprecationWarning: DataModule.prepare_data has already been called, so it will not be called again. In v1.6 this behavior will change to always call DataModule.prepare_data.
  rank_zero_deprecation(
Global seed set to 1234
Loading dataset:   9% 6/64 [00:01<00:11,  4.92it/s]
--------------------------------------------------------------------------------
DATALOADER:0 VALIDATE RESULTS
{'val/acc': 0.9788607358932495,
 'val/ce_loss': 0.0,
 'val/dice_loss': 0.0,
 'val/loss': 0.7917288541793823,
 'val/macc': 0.6826105713844299,
 'val/mdice': 0.5910655856132507,
 'val/mdice_8': 0.646384596824646,
 'val/mdice_nobg': 0.5603470802307129,
 'val/miou': 0.45327597856521606}
--------------------------------------------------------------------------------
GB: END trainer.validate(datamodule=dm)
GB: START trainer.test(datamodule=dm)
Loading dataset: 100% 64/64 [00:02<00:00, 30.14it/s]
Loading dataset: 100% 64/64 [00:02<00:00, 29.84it/s]
LOCAL_RANK: 0 - CUDA_VISIBLE_DEVICES: [0]
Traceback (most recent call last):
  File "main.py", line 180, in <module>
    evaluate(args)
  File "main.py", line 171, in evaluate
    trainer.test(model, datamodule=dm)
  File "/usr/local/lib/python3.8/site-packages/pytorch_lightning/trainer/trainer.py", line 705, in test
    results = self._run(model)
  File "/usr/local/lib/python3.8/site-packages/pytorch_lightning/trainer/trainer.py", line 922, in _run
    self._dispatch()
  File "/usr/local/lib/python3.8/site-packages/pytorch_lightning/trainer/trainer.py", line 986, in _dispatch
    self.accelerator.start_evaluating(self)
  File "/usr/local/lib/python3.8/site-packages/pytorch_lightning/accelerators/accelerator.py", line 95, in start_evaluating
    self.training_type_plugin.start_evaluating(trainer)
  File "/usr/local/lib/python3.8/site-packages/pytorch_lightning/plugins/training_type/training_type_plugin.py", line 165, in start_evaluating
    self._results = trainer.run_stage()
  File "/usr/local/lib/python3.8/site-packages/pytorch_lightning/trainer/trainer.py", line 997, in run_stage
    return self._run_evaluate()
  File "/usr/local/lib/python3.8/site-packages/pytorch_lightning/trainer/trainer.py", line 1077, in _run_evaluate
    self._evaluation_loop.reload_evaluation_dataloaders()
  File "/usr/local/lib/python3.8/site-packages/pytorch_lightning/loops/dataloader/evaluation_loop.py", line 170, in reload_evaluation_dataloaders
    self.trainer.reset_test_dataloader(model)
  File "/usr/local/lib/python3.8/site-packages/pytorch_lightning/trainer/data_loading.py", line 452, in reset_test_dataloader
    self.num_test_batches, self.test_dataloaders = self._reset_eval_dataloader(model, "test")
  File "/usr/local/lib/python3.8/site-packages/pytorch_lightning/trainer/data_loading.py", line 402, in _reset_eval_dataloader
    num_batches = len(dataloader) if has_len(dataloader) else float("inf")
  File "/usr/local/lib/python3.8/site-packages/pytorch_lightning/utilities/data.py", line 63, in has_len
    raise ValueError("`Dataloader` returned 0 length. Please make sure that it returns at least 1 batch")
ValueError: `Dataloader` returned 0 length. Please make sure that it returns at least 1 batch
# Train: 2210, # Val: 1568, # Test: 0...