
Validation sanity check:   0% 0/2 [00:00<?, ?it/s]
  | Name      | Type          | Params
--------------------------------------------
0 | encoder   | BEiT3D        | 86.6 M
1 | decoder   | UPerHead      | 74.9 M
2 | criterion | DiceFocalLoss | 0
--------------------------------------------
161 M     Trainable params
0         Non-trainable params
161 M     Total params
646.213   Total estimated model params size (MB)
/usr/local/lib/python3.8/site-packages/torch/nn/functional.py:3060: UserWarning: Default upsampling behavior when mode=bilinear is changed to align_corners=False since 0.4.0. Please specify align_corners=True if the old behavior is desired. See the documentation of nn.Upsample for details.
  warnings.warn("Default upsampling behavior when mode={} is changed "






































Epoch 0:  80% 760/951 [21:54<05:29,  1.73s/it, loss=0.396, v_num=4tbc]











Validating: 100% 208/208 [02:19<00:00,  1.46it/s]
/usr/local/lib/python3.8/site-packages/torch/optim/lr_scheduler.py:216: UserWarning: Please also save or load the state of the optimizer when saving or loading the scheduler.







































Epoch 1:  80% 760/951 [21:42<05:26,  1.71s/it, loss=0.262, v_num=4tbc]
Validating:   0% 0/208 [00:00<?, ?it/s]
/usr/local/lib/python3.8/site-packages/pytorch_lightning/trainer/trainer.py:1051: UserWarning: Detected KeyboardInterrupt, attempting graceful shutdown...
  rank_zero_warn("Detected KeyboardInterrupt, attempting graceful shutdown...")
/usr/local/lib/python3.8/site-packages/pytorch_lightning/core/datamodule.py:423: LightningDeprecationWarning: DataModule.prepare_data has already been called, so it will not be called again. In v1.6 this behavior will change to always call DataModule.prepare_data.
  rank_zero_deprecation(
Global seed set to 1234


Loading dataset: 100% 64/64 [00:05<00:00, 19.08it/s]



# Train: 1486, # Val: 416, # Test: 0...
Epoch 1:  82% 780/951 [22:18<04:53,  1.71s/it, loss=0.262, v_num=4tbc]











DATALOADER:0 VALIDATE RESULTS10<00:00,  1.60it/s]
{'val/acc': 0.9817813038825989,
 'val/ce_loss': 0.0,
 'val/dice_loss': 0.0,
 'val/loss': 0.3756471276283264,
 'val/macc': 0.7834427952766418,
 'val/mdice': 0.7909407019615173,
 'val/mdice_nobg': 0.7236083149909973,
 'val/miou': 0.6775949597358704}
--------------------------------------------------------------------------------
Global seed set to 12343/64 [00:04<00:00, 12.58it/s]



Loading dataset:  98% 63/64 [00:06<00:00, 12.45it/s]



LOCAL_RANK: 0 - CUDA_VISIBLE_DEVICES: [0] 12.32it/s]
Traceback (most recent call last):
  File "main.py", line 164, in <module>
    args = parse_args()
  File "main.py", line 123, in train
    trainer.fit(model, datamodule=dm)
  File "/usr/local/lib/python3.8/site-packages/pytorch_lightning/trainer/trainer.py", line 705, in test
    results = self._run(model)
  File "/usr/local/lib/python3.8/site-packages/pytorch_lightning/trainer/trainer.py", line 922, in _run
    self._dispatch()
  File "/usr/local/lib/python3.8/site-packages/pytorch_lightning/trainer/trainer.py", line 986, in _dispatch
    self.accelerator.start_evaluating(self)
  File "/usr/local/lib/python3.8/site-packages/pytorch_lightning/accelerators/accelerator.py", line 95, in start_evaluating
    self.training_type_plugin.start_evaluating(trainer)
  File "/usr/local/lib/python3.8/site-packages/pytorch_lightning/plugins/training_type/training_type_plugin.py", line 165, in start_evaluating
    self._results = trainer.run_stage()
  File "/usr/local/lib/python3.8/site-packages/pytorch_lightning/trainer/trainer.py", line 997, in run_stage
    return self._run_evaluate()
  File "/usr/local/lib/python3.8/site-packages/pytorch_lightning/trainer/trainer.py", line 1077, in _run_evaluate
    self._evaluation_loop.reload_evaluation_dataloaders()
  File "/usr/local/lib/python3.8/site-packages/pytorch_lightning/loops/dataloader/evaluation_loop.py", line 170, in reload_evaluation_dataloaders
    self.trainer.reset_test_dataloader(model)
  File "/usr/local/lib/python3.8/site-packages/pytorch_lightning/trainer/data_loading.py", line 452, in reset_test_dataloader
    self.num_test_batches, self.test_dataloaders = self._reset_eval_dataloader(model, "test")
  File "/usr/local/lib/python3.8/site-packages/pytorch_lightning/trainer/data_loading.py", line 402, in _reset_eval_dataloader
    num_batches = len(dataloader) if has_len(dataloader) else float("inf")
  File "/usr/local/lib/python3.8/site-packages/pytorch_lightning/utilities/data.py", line 63, in has_len
    raise ValueError("`Dataloader` returned 0 length. Please make sure that it returns at least 1 batch")
ValueError: `Dataloader` returned 0 length. Please make sure that it returns at least 1 batch
# Train: 1486, # Val: 416, # Test: 0...